Workbook

Sheet 物料匯入
A1: 系統碼 * | B1: 類別碼 * | C1: 流水號 * | D1: 型式碼 * | E1: 料號（自動） | F1: 物料名稱 * | G1: 規格 | H1: 單位 * | I1: 物料屬性（自動） | J1: 系統名稱（自動） | K1: 子系統（選填） | L1: 類別名稱（選填） | M1: 安全等級 | N1: 可修件 | O1: 序號管理 | P1: 請購點 | Q1: 交期天數 | R1: 預估單價 | S1: 市售品 | T1: 檢討說明
A2: 50 | B2: 83 | C2: 0001 | D2: LO | E2: =IF($A2="","",$A2&"."&$B2&"."&$C2&"."&$D2) | F2: 車門CHT3按鈕墊塊 | G2: 材質:鋁合金或經審查同意耐腐蝕金屬，外圈Ø88±5% | H2: PC | I2: =IFERROR(VLOOKUP($A2,系統碼表!$A:$C,3,FALSE),"") | J2: =IFERROR(VLOOKUP($A2,系統碼表!$A:$C,2,FALSE),"") | K2: 車門系統 | L2: 電聯車特殊設備車門類 | M2: 未分類 | N2: 否 | O2: 否 | P2: 0 | S2: 是 | T2: ← 範例，匯入前請整列刪除
A3: 50 | B3: 88 | C3: 0004 | D3: LO | E3: =IF($A3="","",$A3&"."&$B3&"."&$C3&"."&$D3) | F3: R134快速接頭 | G3: 適用於填充R134冷媒 | H3: ST | I3: =IFERROR(VLOOKUP($A3,系統碼表!$A:$C,3,FALSE),"") | J3: =IFERROR(VLOOKUP($A3,系統碼表!$A:$C,2,FALSE),"") | K3: 空調與通風系統 | L3: 電聯車特殊設備空調類 | N3: 否 | O3: 否 | P3: 0 | S3: 是 | T3: ← 範例，匯入前請整列刪除
A4: 50 | B4: 94 | C4: 0054 | D4: LO | E4: =IF($A4="","",$A4&"."&$B4&"."&$C4&"."&$D4) | F4: （消耗品範例） | H4: PC | I4: =IFERROR(VLOOKUP($A4,系統碼表!$A:$C,3,FALSE),"") | J4: =IFERROR(VLOOKUP($A4,系統碼表!$A:$C,2,FALSE),"") | L4: 電聯車雜項類 | N4: 否 | O4: 否 | P4: 0 | S4: 是 | T4: ← 範例，匯入前請整列刪除
E5: =IF($A5="","",$A5&"."&$B5&"."&$C5&"."&$D5) | I5: =IFERROR(VLOOKUP($A5,系統碼表!$A:$C,3,FALSE),"") | J5: =IFERROR(VLOOKUP($A5,系統碼表!$A:$C,2,FALSE),"")
E6: =IF($A6="","",$A6&"."&$B6&"."&$C6&"."&$D6) | I6: =IFERROR(VLOOKUP($A6,系統碼表!$A:$C,3,FALSE),"") | J6: =IFERROR(VLOOKUP($A6,系統碼表!$A:$C,2,FALSE),"")
E7: =IF($A7="","",$A7&"."&$B7&"."&$C7&"."&$D7) | I7: =IFERROR(VLOOKUP($A7,系統碼表!$A:$C,3,FALSE),"") | J7: =IFERROR(VLOOKUP($A7,系統碼表!$A:$C,2,FALSE),"")
E8: =IF($A8="","",$A8&"."&$B8&"."&$C8&"."&$D8) | I8: =IFERROR(VLOOKUP($A8,系統碼表!$A:$C,3,FALSE),"") | J8: =IFERROR(VLOOKUP($A8,系統碼表!$A:$C,2,FALSE),"")
E9: =IF($A9="","",$A9&"."&$B9&"."&$C9&"."&$D9) | I9: =IFERROR(VLOOKUP($A9,系統碼表!$A:$C,3,FALSE),"") | J9: =IFERROR(VLOOKUP($A9,系統碼表!$A:$C,2,FALSE),"")
E10: =IF($A10="","",$A10&"."&$B10&"."&$C10&"."&$D10) | I10: =IFERROR(VLOOKUP($A10,系統碼表!$A:$C,3,FALSE),"") | J10: =IFERROR(VLOOKUP($A10,系統碼表!$A:$C,2,FALSE),"")
E11: =IF($A11="","",$A11&"."&$B11&"."&$C11&"."&$D11) | I11: =IFERROR(VLOOKUP($A11,系統碼表!$A:$C,3,FALSE),"") | J11: =IFERROR(VLOOKUP($A11,系統碼表!$A:$C,2,FALSE),"")
E12: =IF($A12="","",$A12&"."&$B12&"."&$C12&"."&$D12) | I12: =IFERROR(VLOOKUP($A12,系統碼表!$A:$C,3,FALSE),"") | J12: =IFERROR(VLOOKUP($A12,系統碼表!$A:$C,2,FALSE),"")
E13: =IF($A13="","",$A13&"."&$B13&"."&$C13&"."&$D13) | I13: =IFERROR(VLOOKUP($A13,系統碼表!$A:$C,3,FALSE),"") | J13: =IFERROR(VLOOKUP($A13,系統碼表!$A:$C,2,FALSE),"")
E14: =IF($A14="","",$A14&"."&$B14&"."&$C14&"."&$D14) | I14: =IFERROR(VLOOKUP($A14,系統碼表!$A:$C,3,FALSE),"") | J14: =IFERROR(VLOOKUP($A14,系統碼表!$A:$C,2,FALSE),"")
E15: =IF($A15="","",$A15&"."&$B15&"."&$C15&"."&$D15) | I15: =IFERROR(VLOOKUP($A15,系統碼表!$A:$C,3,FALSE),"") | J15: =IFERROR(VLOOKUP($A15,系統碼表!$A:$C,2,FALSE),"")
E16: =IF($A16="","",$A16&"."&$B16&"."&$C16&"."&$D16) | I16: =IFERROR(VLOOKUP($A16,系統碼表!$A:$C,3,FALSE),"") | J16: =IFERROR(VLOOKUP($A16,系統碼表!$A:$C,2,FALSE),"")
... E301: =IF($A301="","",$A301&"."&$B301&"."&$C301&"."&$D301) | I301: =IFERROR(VLOOKUP($A301,系統碼表!$A:$C,3,FALSE),"") | J301: =IFERROR(VLOOKUP($A301,系統碼表!$A:$C,2,FALSE),"")

Sheet 系統碼表
A1: 系統碼 | B1: 系統名稱 | C1: 物料屬性
A2: 32 | B2: 輕軌號誌 | C2: 專屬物料
A3: 35 | B3: 輕軌通訊 | C3: 專屬物料
A4: 39 | B4: 輕軌機廠設備 | C4: 專屬物料
A5: 50 | B5: 輕軌電聯車 | C5: 專屬物料
A6: 91 | B6: 電子類 | C6: 一般物料
A7: 92 | B7: 電機類 | C7: 一般物料
A8: 93 | B8: 機械類 | C8: 一般物料
A9: 94 | B9: 雜項類 | C9: 一般物料
A10: 95 | B10: 工具類 | C10: 一般物料
A11: 96 | B11: 儀器類 | C11: 一般物料

Sheet 類別碼表
A1: 系統碼 | B1: 系統名稱 | C1: 類別碼 | D1: 類別名稱 | E1: 版本
A2: 50 | B2: 輕軌電聯車 | C2: 81 | D2: 電聯車特殊設備煞車類 | E2: 舊
A3: 50 | B3: 輕軌電聯車 | C3: EH | D3: 駕駛式暖氣
A4: 50 | B4: 輕軌電聯車 | C4: 82 | D4: 電聯車特殊設備聯結器類 | E4: 舊
A5: 50 | B5: 輕軌電聯車 | C5: EP | D5: 駕駛室控制面盤
A6: 50 | B6: 輕軌電聯車 | C6: 83 | D6: 電聯車特殊設備車門類 | E6: 舊
A7: 50 | B7: 輕軌電聯車 | C7: ER | D7: 插座(110V)
A8: 50 | B8: 輕軌電聯車 | C8: 84 | D8: 電聯車特殊設備輔助電力類 | E8: 舊
A9: 50 | B9: 輕軌電聯車 | C9: ES | D9: 牽引換流器及輔助電源供應器
A10: 50 | B10: 輕軌電聯車 | C10: 85 | D10: 電聯車特殊設備車體類 | E10: 舊
A11: 50 | B11: 輕軌電聯車 | C11: ET | D11: 空調變頻器
A12: 50 | B12: 輕軌電聯車 | C12: 86 | D12: 電聯車特殊設備推進類 | E12: 舊
A13: 50 | B13: 輕軌電聯車 | C13: EU | D13: 集電弓
A14: 50 | B14: 輕軌電聯車 | C14: 87 | D14: 電聯車特殊設備轉向架及懸吊類 | E14: 舊
A15: 50 | B15: 輕軌電聯車 | C15: KA | D15: 空調風道
A16: 50 | B16: 輕軌電聯車 | C16: 88 | D16: 電聯車特殊設備空調類 | E16: 舊
A17: 50 | B17: 輕軌電聯車 | C17: KC | D17: 駕駛室
A18: 50 | B18: 輕軌電聯車 | C18: 89 | D18: 電聯車特殊設備其他類 | E18: 舊
A19: 50 | B19: 輕軌電聯車 | C19: KG | D19: 車間通道
A20: 50 | B20: 輕軌電聯車 | C20: 91 | D20: 電聯車電子類 | E20: 舊
A21: 50 | B21: 輕軌電聯車 | C21: KL | D21: 車廂
A22: 50 | B22: 輕軌電聯車 | C22: 92 | D22: 電聯車電機類 | E22: 舊
A23: 50 | B23: 輕軌電聯車 | C23: KS | D23: 結構
A24: 50 | B24: 輕軌電聯車 | C24: 93 | D24: 電聯車機械類 | E24: 舊
A25: 50 | B25: 輕軌電聯車 | C25: KT | D25: 內裝
A26: 50 | B26: 輕軌電聯車 | C26: 94 | D26: 電聯車雜項類 | E26: 舊
A27: 50 | B27: 輕軌電聯車 | C27: KW | D27: 玻璃
A28: 50 | B28: 輕軌電聯車 | C28: 95 | D28: 電聯車特殊工具 | E28: 舊
A29: 50 | B29: 輕軌電聯車 | C29: LE | D29: 車外照明
A30: 50 | B30: 輕軌電聯車 | C30: BA | D30: 空氣壓縮機 | E30: 舊
A31: 50 | B31: 輕軌電聯車 | C31: LT | D31: 車內照明
A32: 50 | B32: 輕軌電聯車 | C32: BB | D32: 煞車主機總成 | E32: 舊
A33: 50 | B33: 輕軌電聯車 | C33: PA | D33: 感抗器，推進
A34: 50 | B34: 輕軌電聯車 | C34: BC | D34: 排障器 | E34: 舊
A35: 50 | B35: 輕軌電聯車 | C35: PB | D35: 鼓風機，推進
A36: 50 | B36: 輕軌電聯車 | C36: BD | D36: 碟式煞車總成 | E36: 舊
A37: 50 | B37: 輕軌電聯車 | C37: PG | D37: 齒輪箱及連軸器
A38: 50 | B38: 輕軌電聯車 | C38: BE | D38: 液壓單元 | E38: 舊
A39: 50 | B39: 輕軌電聯車 | C39: PL | D39: 高速斷路器
A40: 50 | B40: 輕軌電聯車 | C40: BF | D40: 輔助液壓單元 | E40: 舊
...

Sheet 子系統清單
A1: 代碼 | B1: 子系統名稱
A2: DOOR | B2: 車門系統
A3: COUPLER | B3: 車間連結系統
A4: CONTROL | B4: 車輛操作及控制設備系統
A5: BODY | B5: 車體系統
A6: HVAC | B6: 空調與通風系統
A7: BRAKE | B7: 煞車系統
A8: LIGHT | B8: 照明系統
A9: PROP | B9: 電力與推進系統
A10: SAFETY | B10: 監控與安全裝置系統
A11: BOGIE | B11: 轉向架系統
A12: COMM | B12: 車載通訊系統
A13: SIGNAL | B13: 車載號誌系統

Sheet 單位表
A1: 單位 | B1: 說明
A2: ST | B2: 組/套
A3: PC | B3: 個/件
A4: SET | B4: 組
A5: EA | B5: 個
A6: PCS | B6: 片
A7: M | B7: 公尺
A8: L | B8: 公升
A9: CAN | B9: 罐
A10: BOX | B10: 箱

Sheet 填寫說明
B1: 淡海輕軌 物料匯入範本 — 填寫說明
A3: A | B3: 一、編碼格式（料號 = 系統碼.類別碼.流水號.型式碼，共10碼）
B4: 料號由前4欄自動組成，例如 50.83.0001.LO。請勿手填「料號」欄。
A6: B | B6: 二、必填欄位（標 *）：系統碼、類別碼、流水號、型式碼、物料名稱、單位
A8: C | B8: 三、各欄位 → 資料庫 material 對照
B9: 系統碼→system_code 類別碼→category_code 流水號→sequence_no 型式碼→type_code
B10: 料號→part_no 物料名稱→material_name 規格→spec 單位→unit
B11: 物料屬性→material_property 系統名稱→system_name 類別名稱→category_name
B12: 安全等級→safety_level 可修件→repairable 序號管理→is_serialized
B13: 請購點→reorder_point 交期天數→lead_time_days 預估單價→estimated_unit_price
B14: 市售品→market_available 檢討說明→review_note
A16: D | B16: 四、自動欄位（灰底，請勿填）
B17: 料號、物料屬性、系統名稱 由公式自動帶出（依系統碼）。
A19: E | B19: 五、取值規則
B20: 系統碼：下拉 10 碼（見「系統碼表」）。類別碼：見「類別碼表」依系統碼查。
B21: 單位：下拉（見「單位表」），可自行輸入其他。
B22: 可修件／序號管理／市售品：是 或 否。安全等級：1/2/3/4/未分類。
B23: is_active 不需填，匯入時預設為「啟用」。
A25: F | B25: 六、子系統（選填）
B26: 「子系統」是車輛功能分類（12項，見「子系統清單」），與官方系統碼是不同維度；
B27: 目前資料庫尚無獨立欄位，先當標記。若要正式儲存，需新增欄位（待決定）。
A29: G | B29: 七、匯入前務必刪除 3 列黃底「範例」資料。
